Workbook

Sheet Summary
B2: Summary Report Spare Parts
B3: Equirement Spare Parts (Present) | D3: Equirement Spare Parts (Need) | F3: Summary Spare Parts
B4: System | C4: Total | D4: System | E4: Total | F4: System | G4: Grand Total
B5: Firewall | C5: 0 | D5: Firewall | E5: =COUNTIF('Additional Order BKK'!B:B,"FW") -> 4 | F5: Firewall | G5: =SUM(C5+E5) -> 4
B6: Access Point (Aruba) | C6: =COUNTIF('Spare Parts All'!B:B,"AP-A") -> 2 | D6: Access Point (Aruba) | E6: =SUM('Additional Order BKK'!F14:F15) -> 4 | F6: Access Point (Aruba) | G6: =SUM(C6+E6) -> 6
B7: Access Point (Ruckus) | C7: =COUNTIF('Spare Parts All'!B:B,"AP-R") -> 7 | D7: Access Point (Ruckus) | E7: =SUM('Additional Order BKK'!F13) -> 2 | F7: Access Point (Ruckus) | G7: =SUM(C7+E7) -> 9
B8: Access Point (Other) | C8: 0 | D8: Access Point (Ruijie) | E8: =SUM('Additional Order BKK'!F22:F23) -> 4 | F8: Access Point (Ruijie) | G8: =SUM(C8+E8) -> 4
B9: Switch 48 Port (Non-POE) | C9: =COUNTIF('Spare Parts All'!B:B,"Switch48 POE") -> 1 | D9: Switch 48 Port (Non-POE) | E9: =COUNTIF('Additional Order BKK'!B:B,"Switch48") -> 0 | F9: Switch 48 Port (Non-POE) | G9: =SUM(C9+E9) -> 1
B10: Switch 48 Port (POE) | C10: =COUNTIF('Spare Parts All'!B:B,"Switch48 POE") -> 1 | D10: Switch 48 Port (POE) | E10: =COUNTIF('Additional Order BKK'!B:B,"Switch48 POE") -> 0 | F10: Switch 48 Port (POE) | G10: =SUM(C10+E10) -> 1
B11: Switch 24 Port (Non-POE) | C11: =COUNTIF('Spare Parts All'!B:B,"Switch24") -> 12 | D11: Switch 24 Port (Non-POE) | E11: =COUNTIF('Additional Order BKK'!B:B,"Switch24") -> 0 | F11: Switch 24 Port (Non-POE) | G11: =SUM(C11+E11) -> 12
B12: Switch 24 Port (POE) | C12: =COUNTIF('Spare Parts All'!B:B,"Switch24 POE") -> 8 | D12: Switch 24 Port (POE) | E12: =COUNTIF('Additional Order BKK'!B:B,"Switch24 POE") -> 1 | F12: Switch 24 Port (POE) | G12: =SUM(C12+E12) -> 9
B13: Switch 8 Port (Non-POE) | C13: =COUNTIF('Spare Parts All'!B:B,"Switch8") -> 1 | D13: Switch 8 Port (Non-POE) | E13: =COUNTIF('Additional Order BKK'!B:B,"Switch8") -> 0 | F13: Switch 8 Port (Non-POE) | G13: =SUM(C13+E13) -> 1
B14: Switch 8 Port (POE) | C14: =COUNTIF('Spare Parts All'!B:B,"Switch8 POE") -> 1 | D14: Switch 8 Port (POE) | E14: =COUNTIF('Additional Order BKK'!B:B,"Switch8 POE") -> 0 | F14: Switch 8 Port (POE) | G14: =SUM(C14+E14) -> 1
B15: CCTV (Dome) | C15: =COUNTIF('Spare Parts All'!B:B,"CCTV Dome") -> 13 | D15: CCTV (Dome) | E15: =COUNTIF('Additional Order BKK'!B:B,"CCTV Dome") -> 0 | F15: CCTV (Dome) | G15: =SUM(C15+E15) -> 13
B16: CCTV (Bullet) | C16: =COUNTIF('Spare Parts All'!B:B,"CCTV Bullet") -> 0 | D16: CCTV (Bullet) | E16: =SUM('Additional Order BKK'!F24:F25) -> 6 | F16: CCTV (Bullet) | G16: =SUM('Additional Order BKK'!F24:F25) -> 6
B17: NVR | C17: =COUNTIF('Spare Parts All'!B:B,"NVR") -> 0 | D17: NVR | E17: =COUNTIF('Additional Order BKK'!B:B,"NVR") -> 1 | F17: NVR | G17: =SUM(C17+E17) -> 1
B18: Mini Gbic | C18: =COUNTIF('Spare Parts All'!B:B,"Mini Gbic") -> 39 | D18: Mini Gbic (TP-Link) | E18: ='Additional Order BKK'!F21 -> 2 | F18: Mini Gbic | G18: =SUM(C18+E18) -> 41
B19: Fiber Cable | C19: =COUNTIF('Spare Parts All'!B:B,"Fiber") -> 0 | D19: Fiber Cable | E19: =SUM('Additional Order BKK'!F19,'Additional Order BKK'!F5:F9) -> 25 | F19: Fiber Cable | G19: =SUM(C19+E19) -> 25
B20: Media Converter | C20: =COUNTIF('Spare Parts All'!B:B,"Media Converter") -> 0 | D20: Media Converter | E20: =COUNTIF('Additional Order BKK'!B:B,"Media Converter") -> 1 | F20: Media Converter | G20: =SUM(C20+E20) -> 1
B21: IPCXS-ACHT | C21: 0 | D21: IPCXS-ACHT | E21: 1 | F21: IPCXS-ACHT | G21: 1
B22: GCD-CP10 SV9100 CPU | C22: 0 | D22: GCD-CP10 SV9100 CPU | E22: 1 | F22: GCD-CP10 SV9100 CPU | G22: 1
B23: GCD-8LCF 8 ANALOG TEL INTERFACE CARD (BASE) | C23: 0 | D23: GCD-8LCF 8 ANALOG TEL INTERFACE CARD (BASE) | E23: 2 | F23: GCD-8LCF 8 ANALOG TEL INTERFACE CARD (BASE) | G23: 2
B24: GPZ-8LCF 8 ANALOG TEL INTERFACE CARD (EXPANSION) | C24: 0 | D24: GPZ-8LCF 8 ANALOG TEL INTERFACE CARD (EXPANSION) | E24: 2 | F24: GPZ-8LCF 8 ANALOG TEL INTERFACE CARD (EXPANSION) | G24: 2
B25: GCD-16DLCA DIGITAL TEL INTERFACE CARD | C25: 0 | D25: GCD-16DLCA DIGITAL TEL INTERFACE CARD | E25: 2 | F25: GCD-16DLCA DIGITAL TEL INTERFACE CARD | G25: 2
B26: DTZ-24D-3P (BK)TEL DIGITAL KEY TELEPHONE | C26: 0 | D26: DTZ-24D-3P (BK)TEL DIGITAL KEY TELEPHONE | E26: 2 | F26: DTZ-24D-3P (BK)TEL DIGITAL KEY TELEPHONE | G26: 2
B27: Total | C27: =SUM(C5:C26) -> 85 | D27: Total | E27: =SUM(E5:E26) -> 60 | F27: Grand Total | G27: =SUM(G5:G26) -> 145

Sheet Spare Parts All
A1: SPARE PART SERVICE BANGKOK
L6: การยืมอุปกรณ์
A7: No | B7: Type | C7: Brand | D7: Material Code | E7: Code (Model) | F7: PRODUCT NAME | G7: Qty | H7: Cost (Total) | I7: Status | J7: Serail Number | K7: Remark | L7: Name | M7: Date Start | N7: Date End | O7: Project | P7: Remark
A8: 1 | B8: AP-A | C8: Aruba | D8: ONWS005C500001 | E8: IAP-103-RW | F8: ARUBA INSTANT IAP-103 WIRELESS ACCESS POINT, 802.11N, 2X2:2, DUAL RADIO, INTEGRATED ANTENNAS | G8: 1 | H8: 3700 | I8: In Service | J8: CU0407405 | K8: ของอยู่ห้อง service
A9: 2 | B9: AP-A | C9: Aruba | D9: ONWS005C500001 | E9: IAP-103-RW | F9: ARUBA INSTANT IAP-103 WIRELESS ACCESS POINT, 802.11N, 2X2:2, DUAL RADIO, INTEGRATED ANTENNAS | G9: 1 | H9: 3700 | I9: In Service | J9: CU0407371 | K9: ของอยู่ห้อง service
A10: 3 | B10: AP-C | C10: Cisco | D10: ONWS005F900001 | E10: MR36-HW | F10: ARUBA INSTANT IAP-103 WIRELESS ACCESS POINT, 802.11N, 2X2:2, DUAL RADIO, INTEGRATED ANTENNAS | G10: 1 | H10: 20300 | I10: In Service | J10: Q3AJ-F4ST-5SPJ | K10: ของอยู่ห้อง service
A11: 4 | B11: AP-R | C11: Ruckus | D11: ONWS0050400001 | E11: 901-H320-WW00 | F11: H320 ZONEFLEX 802.11AC WAVE 2 DUAL-BAND CONCURRENT 2.4 GHZ (1X1:1) & 5 GHZ (2X2:2), WIRED/WIRELESS WALL SWITCH, MU-MIMO, BEAMFLEX+, 1 10/100/1000 & 2 10/100 ETHERNET ACCESS PORTS, POE IN | G11: 1 | H11: 6700 | I11: In Service | J11: 411702001737 | K11: ของอยู่ห้อง service
A12: 5 | B12: AP-R | C12: Ruckus | D12: ONWS0052000001 | E12: 901-R610-WW00 | F12: RUCKUS R610 DUAL-BAND 802.11ABGN/AC (802.11AC WAVE 2) WIRELESS ACCESS POINT, 3X3:3 STREAMS, MU-MIMO, BEAMFLEX+, DUAL PORTS, 802.3AF/AT POE SUPPORT. DOES NOT INCLUDE POWER ADAPTER OR POE INJECTOR. INCLUDES LIMITED LIFETIME WARRANTY. | G12: 1 | H12: 19795 | I12: ห้อง PJ | J12: 331849004133 | K12: ห้องพี่ตุ๊ก
A13: 6 | B13: AP-R | C13: Ruckus | D13: ONWS0052200001 | E13: 901-R710-WW00 | F13: RUCKUS [ZONEFLEX] R710 DUAL-BAND 802.11ABGN/AC WIRELESS ACCESS POI | G13: 1 | H13: 23500 | I13: In Service | J13: 511603004028 | K13: ของอยู่ห้อง service
A14: 7 | B14: AP-R | C14: Ruckus | D14: ONWS0052200001 | E14: 901-R710-WW00 | F14: RUCKUS [ZONEFLEX] R710 DUAL-BAND 802.11ABGN/AC WIRELESS ACCESS POI | G14: 1 | H14: 23500 | I14: In Service | J14: 511603004151 | K14: ของอยู่ห้อง service
A15: 8 | B15: CCTV Dome | C15: Hikvision | D15: OCCV0053000001 | E15: DS-2CD1323G0-IUF(2.8mm)(C) | F15: Turret Camera | G15: 1 | H15: 5800 | I15: In Service | J15: J86864498 | K15: capella ยืม | L15: 19/2/2025
A16: 9 | B16: CCTV Dome | C16: Hikvision | D16: OCCV0053000001 | E16: DS-2CD1323G0-IUF(2.8mm)(C) | F16: Turret Camera | G16: 1 | H16: 5800 | I16: In Service | J16: J86863598 | K16: ของอยู่ห้อง service | L16: Ball | O16: PTT
A17: 10 | B17: CCTV Dome | C17: Hikvision | D17: OCCV0053000001 | E17: DS-2CD1323G0-IUF(2.8mm)(C) | F17: Turret Camera | G17: 1 | H17: 5800 | I17: In Service | J17: J86864830 | K17: ของอยู่ห้อง service | L17: Ball | O17: PTT
A18: 11 | B18: CCTV Dome | C18: Hikvision | D18: OCCV0056100001 | E18: DS-2CD2123G2-IU(2.8mm) | F18: HIKVISION 2 MP Vandal Built-in Mic Fixed Dome Network Camera, (1/2.8"Progressive Scan CMOS/1920x1080/LUX0.005/Fixed focal lens 4mm./H.265+/IR:30m/120dB WDR/IP67) | G18: 1 | H18: 7380 | I18: In Service | J18: F92493578 | K18: ของอยู่ห้อง service | L18: Ball | O18: PTT
A19: 12 | B19: CCTV Dome | C19: Hikvision | D19: OCCV0056100001 | E19: DS-2CD2123G2-IU(2.8mm) | F19: HIKVISION 2 MP Vandal Built-in Mic Fixed Dome Network Camera, (1/2.8"Progressive Scan CMOS/1920x1080/LUX0.005/Fixed focal lens 4mm./H.265+/IR:30m/120dB WDR/IP67) | G19: 1 | H19: 7380 | I19: In Service | J19: F92493513 | K19: ติดตั้ง ห้อง service | L19: Ball | O19: PTT
A20: 13 | B20: CCTV Dome | C20: Hikvision | D20: OCCV0056100001 | E20: DS-2CD2123G2-IU(2.8mm) | F20: HIKVISION 2 MP Vandal Built-in Mic Fixed Dome Network Camera, (1/2.8"Progressive Scan CMOS/1920x1080/LUX0.005/Fixed focal lens 4mm./H.265+/IR:30m/120dB WDR/IP67) | G20: 1 | H20: 7380 | I20: In Service | J20: F92493503 | K20: ของอยู่ห้อง service | L20: Ball | O20: PTT
A21: 14 | B21: CCTV Dome | C21: Wisenet | D21: OCCV005V300001 | E21: LND-6030R | F21: 2M H.264 NW IR DOME, FIXED LENS 6MM ,DAY & NIGHT (ICR), WDR (120DB) ,HALLWAY VIEW, IR VIEWABLE | G21: 1 | H21: 5040 | I21: In Service | J21: ZGEC6V4RA0000QP | K21: ของอยู่ห้อง service
A22: 15 | B22: CCTV Dome | C22: Wisenet | D22: OCCV005V300001 | E22: LND-6030R | F22: 2M H.264 NW IR DOME, FIXED LENS 6MM ,DAY & NIGHT (ICR), WDR (120DB) ,HALLWAY VIEW, IR VIEWABLE | G22: 1 | H22: 5040 | I22: In Service | J22: ZGEC6V4RA0000RN | K22: ของอยู่ห้อง service
A23: 16 | B23: CCTV Dome | C23: Wisenet | D23: OCCV005V300001 | E23: LND-6030R | F23: 2M H.264 NW IR DOME, FIXED LENS 6MM ,DAY & NIGHT (ICR), WDR (120DB) ,HALLWAY VIEW, IR VIEWABLE | G23: 1 | H23: 5040 | I23: In Service | J23: ZGEC6V4RA0000SR | K23: ของอยู่ห้อง service
A24: 17 | B24: Mini Gbic | C24: Aruba | D24: ONWS0407200001 | E24: NX-J4859C | F24: 1000BASE-LX SFP, 20KM, SINGLE MODE | G24: 1 | H24: 2364 | I24: In Service | J24: HPB191221025 | K24: ของอยู่ห้อง service
A25: 18 | B25: Mini Gbic | C25: Aruba | D25: ONWS0407200001 | E25: NX-J4859C | F25: 1000BASE-LX SFP, 20KM, SINGLE MODE | G25: 1 | H25: 2364 | I25: In Service | J25: HPB191221026 | K25: ของอยู่ห้อง service
A26: 19 | B26: Mini Gbic | C26: Aruba | D26: ONWS0407200001 | E26: NX-J4859C | F26: 1000BASE-LX SFP, 20KM, SINGLE MODE | G26: 1 | H26: 2364 | I26: In Service | J26: HPB191221027 | K26: ของอยู่ห้อง service
A27: 20 | B27: Mini Gbic | C27: Aruba | D27: ONWS0407200001 | E27: NX-J4859C | F27: 1000BASE-LX SFP, 20KM, SINGLE MODE | G27: 1 | H27: 2364 | I27: In Service | J27: HPB191221028 | K27: KIS | L27: MARK Kis | M27: 45766 | O27: KIS
A28: 21 | B28: Mini Gbic | C28: Aruba | D28: ONWS0407200001 | E28: NX-J4859C | F28: 1000BASE-LX SFP, 20KM, SINGLE MODE | G28: 1 | H28: 2364 | I28: In Service | J28: HPB191221029 | K28: ของอยู่ห้อง service
A29: 22 | B29: Mini Gbic | C29: Aruba | D29: ONWS0407200001 | E29: NX-J4859C | F29: 1000BASE-LX SFP, 20KM, SINGLE MODE | G29: 1 | H29: 2364 | I29: In Service | J29: HPB191221030 | K29: ของอยู่ห้อง service
A30: 23 | B30: Mini Gbic | C30: Cisco | D30: ONWS0400800001 | E30: AZ-GLC-SX-MMD | F30: 1000BASE-SX SFP, 550M, MULITMODE WITH DOM | G30: 1 | H30: 425.52 | I30: In Service | J30: CIB170621088 | K30: ของอยู่ห้อง service
A31: 24 | B31: Mini Gbic | C31: Cisco | D31: ONWS0400900001 | E31: AZ-GLC-T | F31: 1000 BASE SFP-T RJ45, 100 M | G31: 1 | H31: 8000 | I31: In Service | J31: CIB170517721 | K31: ของอยู่ห้อง service | L31: Big | O31: pack in radison จำหน่ายออก
A32: 25 | B32: Mini Gbic | C32: Cisco | D32: ONWS0400900001 | E32: AZ-GLC-T | F32: 1000 BASE SFP-T RJ45, 100 M | G32: 1 | H32: =H31 -> 8000 | I32: In Service | J32: CIB170517722 | K32: ของอยู่ห้อง service | L32: Dew | O32: pack in radison จำหน่ายออก
B33: Mini Gbic | C33: Link | D33: 8859206778808 | E33: UT-903T-LC | F33: 1.25 SFP RJ45 10/100/1000Base-T 100m | G33: 1 | H33: 4000 | I33: In Service | J33: 25010601634 | K33: ของอยู่ห้อง service | O33: คืน Radisson
B34: Mini Gbic | C34: Link | D34: 8859206778808 | E34: UT-903T-LC | F34: 1.25 SFP RJ45 10/100/1000Base-T 100m | G34: 1 | H34: 4000 | I34: In Service | J34: 25010601633 | K34: ของอยู่ห้อง service | O34: คืน Radisson
B35: Mini Gbic | C35: Link | D35: 8859206778808 | E35: UT-903T-LC | F35: 1.25 SFP RJ45 10/100/1000Base-T 100m | G35: 1 | H35: 4000 | I35: In Service | J35: 25010601637 | K35: ของอยู่ห้อง service | O35: คืน Radisson
A36: 26 | B36: Mini Gbic | C36: Cisco | D36: ONWS0400900001 | E36: AZ-GLC-T | F36: 1000 BASE SFP-T RJ45, 100 M | G36: 1 | H36: =H31 -> 8000 | I36: In Service | J36: CIB170517723 | K36: ของอยู่ห้อง service
A37: 27 | B37: Mini Gbic | C37: Cisco | D37: ONWS0400900001 | E37: AZ-GLC-T | F37: 1000 BASE SFP-T RJ45, 100 M | G37: 1 | H37: =H31 -> 8000 | I37: In Service | J37: CIB170517724 | K37: ของอยู่ห้อง service | L37: Dew | O37: pack in radison จำหน่ายออก
A38: 28 | B38: Mini Gbic | C38: Cisco | D38: ONWS0401500001 | E38: AZ-MGBLX1 | F38: MGBLX1 GIGABIT ETHERNET LX MINI-GBIC SFP TRANSCEIVER/1.25 GB/S 20 KM. LC 3.3 V | G38: 1 | H38: 3520 | I38: In Service | J38: CIB171204384 | K38: ของอยู่ห้อง service
A39: 29 | B39: Mini Gbic | C39: Cisco | D39: ONWS0401500001 | E39: AZ-MGBLX1 | F39: MGBLX1 GIGABIT ETHERNET LX MINI-GBIC SFP TRANSCEIVER/1.25 GB/S 20 KM. LC 3.3 V | G39: 1 | H39: 3520 | I39: In Service | J39: CIB171204385 | K39: ของอยู่ห้อง service
A40: 30 | B40: Mini Gbic | C40: Cisco | D40: ONWS0401500001 | E40: AZ-MGBLX1 | F40: MGBLX1 GIGABIT ETHERNET LX MINI-GBIC SFP TRANSCEIVER/1.25 GB/S 20 KM. LC 3.3 V | G40: 1 | H40: 3520 | I40: In Service | J40: CIB171204386 | K40: ของอยู่ห้อง service
A41: 31 | B41: Mini Gbic | C41: Cisco | D41: ONWS0401500001 | E41: AZ-MGBLX1 | F41: MGBLX1 GIGABIT ETHERNET LX MINI-GBIC SFP TRANSCEIVER/1.25 GB/S 20 KM. LC 3.3 V | G41: 1 | H41: 3520 | I41: In Service | J41: CIB171204387 | K41: ของอยู่ห้อง service
A42: 32 | B42: Mini Gbic | C42: Cisco | D42: ONWS0401500001 | E42: AZ-MGBLX1 | F42: MGBLX1 GIGABIT ETHERNET LX MINI-GBIC SFP TRANSCEIVER/1.25 GB/S 20 KM. LC 3.3 V | G42: 1 | H42: 3520 | I42: In Service | J42: CIB171204388 | K42: ของอยู่ห้อง service
A43: 33 | B43: Mini Gbic | C43: Cisco | D43: ONWS0401500001 | E43: AZ-MGBLX1 | F43: MGBLX1 GIGABIT ETHERNET LX MINI-GBIC SFP TRANSCEIVER/1.25 GB/S 20 KM. LC 3.3 V | G43: 1 | H43: 3520 | I43: In Service | J43: CIB171204389 | K43: ของอยู่ห้อง service
A44: 34 | B44: Mini Gbic | C44: Cisco | D44: ONWS0401500001 | E44: AZ-MGBLX1 | F44: MGBLX1 GIGABIT ETHERNET LX MINI-GBIC SFP TRANSCEIVER/1.25 GB/S 20 KM. LC 3.3 V | G44: 1 | H44: 3520 | I44: In Service | J44: CIB171204390 | K44: ของอยู่ห้อง service
...

Sheet Spare Parts REIGNWOOD ปัจจุบัน
A1: SPARE PART SERVICE RAIN WOOD
M6: การยืมอุปกรณ์
A7: No | B7: Type | C7: Brand | D7: Material Code | E7: Code | F7: PRODUCT NAME | G7: Qty | H7: Cost (Total) | I7: Status | J7: Serail Number | K7: MAC ADDRESS | L7: Remark | M7: Name | N7: Date Start | O7: Date End | P7: Project
A8: 1 | B8: CCTV Bullet | C8: Hikvision | E8: DS-2CD3666G2T-IZS 2.7-13.5mm (H) | G8: 1 | I8: In Service | J8: FW2334409 | K8: 54-8C-81-F5-F3-22 | L8: ยังไม่ลงระบบ | M8: Prem | N8: 45938 | Q8: แทน BIK-18
A9: 2 | B9: CCTV Bullet | C9: Hikvision | E9: DS-2CD3666G2T-IZS 2.7-13.5mm (H) | G9: 1 | I9: In Service | J9: FW2334414 | K9: 54-8C-81-F5-F3-27 | L9: ยังไม่ลงระบบ
A10: 3 | B10: CCTV Bullet | C10: Hikvision | E10: DS-2CD3666G2T-IZS 2.7-13.5mm (H) | G10: 1 | I10: In Service | J10: FW2334391 | K10: 54-8C-81-F5-F3-10 | L10: ยังไม่ลงระบบ
A11: 4 | B11: CCTV Bullet | C11: Hikvision | E11: DS-2CD3666G2T-IZS 2.7-13.5mm (H) | G11: 1 | I11: P'Golf | J11: FA8974380 | K11: E8-A0-ED-F9-B9-99 | M11: P'Golf | N11: 45902
A12: 5 | B12: CCTV Bullet | C12: Hikvision | E12: DS-2CD3666G2T-IZS 2.7-13.5mm (H) | G12: 1 | I12: P'Golf | J12: FA8974401 | K12: E8-A0-ED-F9-B9-AE | M12: P'Golf | N12: 45902
A13: 6 | B13: CCTV Bullet | C13: Hikvision | E13: DS-2CD3666G2T-IZS 2.7-13.5mm (H) | G13: 1 | I13: In Service | J13: FA8974445 | K13: E8-A0-ED-F9-B9-DA | L13: ส่งเคลมอยู่
A14: 7 | B14: CCTV Bullet | C14: Hikvision | G14: 1 | I14: P'Kong | L14: เสีย P'Kong PJ เอาไปติด Temp | M14: P'Kong
A15: 8 | B15: CCTV PANORAMA | C15: Hikvision | E15: DS-2CD2T46G2P-ISU/SL 2.8 (C) | G15: 1 | I15: In Service | J15: FA8875580 | K15: E8-A0-ED-F8-C8-DA
A16: 9 | B16: CCTV PANORAMA | C16: Hikvision | E16: DS-2CD2T46G2P-ISU/SL 2.8 (C) | G16: 1 | I16: In Service | J16: FA8875598 | K16: E8-A0-ED-F8-C8-EC
A17: 10 | B17: CCTV PTZ | C17: Hikvision | E17: DS-2SE4C425MWG-E (14F0) | G17: 1 | I17: In Service | J17: FA9117486 | K17: e8-a0-ed-fa-80-87
A18: 11 | B18: HUB Switch | C18: AETEK | E18: H40-044-30-150-V3 | G18: 1 | I18: N'Wave | J18: H43V324040127 | L18: ถอดบอร์ดไปเปลี่ยนแล้วส่งเคลม ต้องเอามาติดคืน | M18: N'Wave | N18: 45901
A19: 12 | B19: แผงไฟไม้กั้น | C19: Hikvision | E19: DZ(LED)-V1.1 ROHS | G19: 1 | I19: In Service | L19: บอร์ดไฟตู้ไม้กั้น
A20: 13 | B20: ลำโพง | C20: Zycoo | E20: SL50 | G20: 1 | I20: In Service | J20: ZSL2100471 | K20: 68692E2A01D7
A21: 14 | B21: SOS | C21: Zycoo | E21: EI-V05 | G21: 1 | I21: In Service | J21: ZEIV52200449 | K21: 68692E2C054D
A22: 15 | B22: Switch 8 Port | C22: LINK | E22: PS-3180 | G22: 1 | I22: In Service | J22: 246020584 | K22: FCD2B61B8DA2 | L22: เสียโดนน้ำเคลมไม่ได้(ยังไม่ได้ลองซ่อมเอง)
A23: 16 | B23: Sersor Smart Pole | C23: SENTEC | E23: SEM227 | I23: In Service | J23: 202504111011 | L23: เคลมกับ Step
A24: 17 | B24: Sersor Smart Pole | C24: SENTEC | E24: SEM227 | I24: In Service | J24: 202504111010 | L24: เคลมกับ Step
G28: Total | H28: =SUM(H7:H26) -> 0
F29: มีในระบบ Center (Spare parts)
F31: ไม่มีในระบบ Center (Spare parts)

Sheet Spare Parts REIGNWOOD (เก่า)
A1: SPARE PART SERVICE RAIN WOOD
L6: การยืมอุปกรณ์
A7: No | B7: Type | C7: Brand | D7: Material Code | E7: Code | F7: PRODUCT NAME | G7: Qty | H7: Cost (Total) | I7: Status | J7: Serail Number | K7: Remark | L7: Name | M7: Date Start | N7: Date End | O7: Project
A8: 1 | B8: CCTV Bullet | C8: Hikvision | D8: OCCV005BG00001 | E8: DS-2CD3666G2T-IZS(2.7-13.5mm)(H) | F8: DS-2CD3666G2T-IZS(2.7-13.5mm)(H)_6MP AcuSense Varifocal Bullet Network Camera, WHITE HIKVISION | G8: 1 | H8: 5940 | I8: In Service | J8: FA8974206 | K8: ยืมไป REIGNWOOD | L8: พี่ตุ๊ก | O8: Project no. 03402024
A9: 2 | B9: CCTV Bullet | C9: Hikvision | D9: OCCV005BG00001 | E9: DS-2CD3T66G2-4IS(2.8mm)(H) | F9: DS-2CD3T66G2-4IS(2.8mm)(H) | G9: 1 | H9: 5940 | I9: In Service | J9: FA8955790 | K9: ของอยู่ห้อง service
A10: 3 | B10: CCTV Bullet | C10: Hikvision | D10: OCCV005BG00001 | E10: DS-2CD3T66G2-4IS(2.8mm)(H) | F10: DS-2CD3T66G2-4IS(2.8mm)(H) | G10: 1 | H10: 5940 | I10: In Service | J10: FA8955832 | K10: ยืมไป REIGNWOOD | L10: พี่ตุ๊ก | O10: Project no. 03402024
A11: 4 | B11: CCTV Bullet | C11: Hikvision | D11: OCCV005BG00001 | E11: DS-2CD3666G2T-IZS(2.7-13.5mm)(H) | F11: DS-2CD3666G2T-IZS(2.7-13.5mm)(H)_6MP AcuSense Varifocal Bullet Network Camera, WHITE HIKVISION | G11: 1 | H11: 5940 | I11: In Service | J11: FA8974395 | K11: ยืมไป REIGNWOOD | L11: พี่ตุ๊ก | O11: Project no. 03402024
A12: 5 | B12: CCTV Bullet | C12: Hikvision | D12: OCCV005BJ00001 | E12: DS-2CD2T46G2P-ISU/SL(2.8mm)(C) | F12: DS-2CD2T46G2P-ISU/SL(2.8mm)(C)_4MP Panoramic AcuSense Fixed Bullet Network Camera, (2x1/2.5"CMOS/Lux:0.003/Fixed lens:2.8mm/IR:Up to HIKVISION | G12: 1 | H12: 4150 | I12: In Service | J12: FA8875580 | K12: ของอยู่ห้อง service | P12: พี่ตุ๊กยืมไปไม่ได้ใช้ คืนแล้ว
A13: 6 | B13: CCTV Bullet | C13: Hikvision | D13: OCCV005BJ00001 | E13: DS-2CD2T46G2P-ISU/SL(2.8mm)(C) | F13: DS-2CD2T46G2P-ISU/SL(2.8mm)(C)_4MP Panoramic AcuSense Fixed Bullet Network Camera, (2x1/2.5"CMOS/Lux:0.003/Fixed lens:2.8mm/IR:Up to HIKVISION | G13: 1 | H13: 4150 | I13: In Service | J13: FA8875598 | K13: ยืมไป REIGNWOOD | L13: พี่ตุ๊ก | O13: Project no. 03402024
A14: 7 | B14: CCTV Bullet | C14: Hikvision | D14: OCCV005BO00001 | E14: DS-2SE4C425MWG-E(14F0) | F14: DS-2SE4C425MWG-E(14F0)_TandemVu 4-inch 4MP 25X Colorful & IR Network Speed Dome, HIKVISION | G14: 1 | H14: 9930 | I14: In Service | J14: FA9117486 | K14: ของอยู่ห้อง service | O14: Project no. 03402024 | P14: ส่งตัวเสียเคลมกลับมาเก็บ | Q14: OLD : FA9117534
A15: 8 | B15: CCTV Bullet | C15: Hikvision | D15: OCCV005BP00001 | E15: DS-2CD3T66G2-4IS(2.8mm)(H) | F15: DS-2CD3T66G2-4IS(2.8mm)(H) | G15: 1 | H15: 5940 | I15: In Service | J15: FA8955793 | K15: ยืมไป REIGNWOOD | L15: พี่ตุ๊ก | O15: Project no. 03402024
A16: 9 | B16: CCTV Bullet | C16: Hikvision | D16: OCCV005BP00001 | E16: DS-2CD3T66G2-4IS(2.8mm)(H) | F16: DS-2CD3T66G2-4IS(2.8mm)(H) | G16: 1 | H16: 5940 | I16: In Service | J16: FA8955802 | K16: ยืมไป REIGNWOOD | L16: พี่ตุ๊ก | O16: Project no. 03402024
A17: 10
G22: Total | H22: =SUM(H7:H20) -> 53870
F23: มีในระบบ Center (Spare parts)
F25: ไม่มีในระบบ Center (Spare parts)

Sheet Spare Parts KIS
A1: SPARE PART SERVICE KIS
L6: การยืมอุปกรณ์
A7: No | B7: Type | C7: Brand | D7: Material Code | E7: Code | F7: PRODUCT NAME | G7: Qty | H7: Cost (Total) | I7: Status | J7: Serail Number | K7: Remark | L7: Name | M7: Date Start | N7: Date End | O7: Project
A8: 1 | B8: AP | C8: Huawei | D8: ONWS005AI00001 | E8: 50084450 | F8: 50084450_AirEngine5761-12W Access Point, (11ax Room Type Indoor/2+2 Dual Frequency/Smart Antenna/USB/Bluetooth/PSE) HUAHEI | G8: 1 | H8: 4352.03 | I8: In Service | J8: 21500844508SP8000893 | K8: Spart part KIS
A9: 2 | B9: AP | C9: Huawei | D9: ONWS005AI00001 | E9: 50084450 | F9: 50084450_AirEngine5761-12W Access Point, (11ax Room Type Indoor/2+2 Dual Frequency/Smart Antenna/USB/Bluetooth/PSE) HUAHEI | G9: 1 | H9: 4352.03 | I9: In Service | J9: 21500844508SP8000765 | K9: Spart part KIS
A10: 3 | B10: AP | C10: Huawei | D10: ONWS005AI00001 | E10: 50084450 | F10: 50084450_AirEngine5761-12W Access Point, (11ax Room Type Indoor/2+2 Dual Frequency/Smart Antenna/USB/Bluetooth/PSE) HUAHEI | G10: 1 | H10: 4352.03 | I10: In Service | J10: 21500844508SP8000840 | K10: Spart part KIS
A11: 4 | B11: AP | C11: Huawei | D11: ONWS005AI00001 | E11: 50084450 | F11: 50084450_AirEngine5761-12W Access Point, (11ax Room Type Indoor/2+2 Dual Frequency/Smart Antenna/USB/Bluetooth/PSE) HUAHEI | G11: 1 | H11: 4352.03 | I11: In Service | J11: 21500844508SP8000767 | K11: Spart part KIS
A12: 5 | B12: AP | C12: Huawei | D12: ONWS005AI00001 | E12: 50084450 | F12: 50084450_AirEngine5761-12W Access Point, (11ax Room Type Indoor/2+2 Dual Frequency/Smart Antenna/USB/Bluetooth/PSE) HUAHEI | G12: 1 | H12: 4352.03 | I12: In Service | J12: 21500844508SP8000922 | K12: Spart part KIS
A13: 6 | B13: AP | C13: Huawei | D13: ONWS005AI00001 | E13: 50084450 | F13: 50084450_AirEngine5761-12W Access Point, (11ax Room Type Indoor/2+2 Dual Frequency/Smart Antenna/USB/Bluetooth/PSE) HUAHEI | G13: 1 | H13: 4352.03 | I13: In Service | J13: 21500844508SP8000920 | K13: Spart part KIS
A14: 7 | B14: AP | C14: Huawei | D14: ONWS005AI00001 | E14: 50084450 | F14: 50084450_AirEngine5761-12W Access Point, (11ax Room Type Indoor/2+2 Dual Frequency/Smart Antenna/USB/Bluetooth/PSE) HUAHEI | G14: 1 | H14: 4352.03 | I14: In Service | J14: 21500844508SP8000122 | K14: Spart part KIS
A15: 8 | B15: AP | C15: Huawei | D15: ONWS005AI00001 | E15: 50084450 | F15: 50084450_AirEngine5761-12W Access Point, (11ax Room Type Indoor/2+2 Dual Frequency/Smart Antenna/USB/Bluetooth/PSE) HUAHEI | G15: 1 | H15: 4352.03 | I15: In Service | J15: 21500844508SP8000768 | K15: Spart part KIS
A16: 9 | B16: CCTV Bullet | C16: Hikvision | D16: OCCV005BF00001 | E16: DS-2CD3643G2-IZS(2.7-13.5mm) | F16: DS-2CD3643G2-IZS(2.7-13.5mm)_4MP AcuSense Motorized Varifocal Bullet Network Camera, HIKVISION | G16: 1 | I16: In Service | J16: AW6095467 | K16: Spart part KIS
A17: 10 | B17: CCTV Bullet | C17: Hikvision | D17: OCCV005BF00001 | E17: DS-2CD3643G2-IZS(2.7-13.5mm) | F17: DS-2CD3643G2-IZS(2.7-13.5mm)_4MP AcuSense Motorized Varifocal Bullet Network Camera, HIKVISION | G17: 1 | I17: In Service | J17: AW6095491 | K17: Spart part KIS
A18: 11 | B18: CCTV Bullet | C18: Hikvision | D18: OCCV005BF00001 | E18: DS-2CD3643G2-IZS(2.7-13.5mm) | F18: DS-2CD3643G2-IZS(2.7-13.5mm)_4MP AcuSense Motorized Varifocal Bullet Network Camera, HIKVISION | G18: 1 | I18: In Service | J18: AW6095408 | K18: Spart part KIS
A19: 12 | B19: CCTV Bullet | C19: Hikvision | D19: OCCV005BF00001 | E19: DS-2CD3643G2-IZS(2.7-13.5mm) | F19: DS-2CD3643G2-IZS(2.7-13.5mm)_4MP AcuSense Motorized Varifocal Bullet Network Camera, HIKVISION | G19: 1 | I19: In Service | J19: AW6095443 | K19: Spart part KIS
A20: 13 | B20: CCTV Dome | C20: Hikvision | D20: OCCV005BF00001 | E20: DS-2CD3643G2-IZS(2.7-13.5mm) | F20: DS-2CD3643G2-IZS(2.7-13.5mm)_4MP AcuSense Motorized Varifocal Bullet Network Camera, HIKVISION | G20: 1 | I20: In Service | J20: AW5569558 | K20: Spart part KIS
A21: 14 | B21: CCTV Dome | C21: Hikvision | D21: OCCV005BF00001 | E21: DS-2CD3643G2-IZS(2.7-13.5mm) | F21: DS-2CD3643G2-IZS(2.7-13.5mm)_4MP AcuSense Motorized Varifocal Bullet Network Camera, HIKVISION | G21: 1 | I21: In Service | J21: AW5569755 | K21: Spart part KIS
A22: 15 | B22: CCTV Dome | C22: Hikvision | D22: OCCV005BF00001 | E22: DS-2CD3643G2-IZS(2.7-13.5mm) | F22: DS-2CD3643G2-IZS(2.7-13.5mm)_4MP AcuSense Motorized Varifocal Bullet Network Camera, HIKVISION | G22: 1 | I22: In Service | J22: AW5569763 | K22: Spart part KIS
A23: 16 | B23: CCTV Dome | C23: Hikvision | D23: OCCV005BF00001 | E23: DS-2CD3643G2-IZS(2.7-13.5mm) | F23: DS-2CD3643G2-IZS(2.7-13.5mm)_4MP AcuSense Motorized Varifocal Bullet Network Camera, HIKVISION | G23: 1 | I23: In Service | J23: AW5569557 | K23: Spart part KIS
A24: 17 | B24: CCTV Dome | C24: Hikvision | D24: OCCV005BF00001 | E24: DS-2CD3643G2-IZS(2.7-13.5mm) | F24: DS-2CD3643G2-IZS(2.7-13.5mm)_4MP AcuSense Motorized Varifocal Bullet Network Camera, HIKVISION | G24: 1 | I24: In Service | J24: AW5569758 | K24: Spart part KIS
A25: 18 | B25: CCTV Dome | C25: Hikvision | D25: OCCV005BF00001 | E25: DS-2CD3643G2-IZS(2.7-13.5mm) | F25: DS-2CD3643G2-IZS(2.7-13.5mm)_4MP AcuSense Motorized Varifocal Bullet Network Camera, HIKVISION | G25: 1 | I25: In Service | J25: AW5569747 | K25: Spart part KIS
A26: 19 | B26: CCTV Dome | C26: Hikvision | D26: OCCV005BF00001 | E26: DS-2CD3643G2-IZS(2.7-13.5mm) | F26: DS-2CD3643G2-IZS(2.7-13.5mm)_4MP AcuSense Motorized Varifocal Bullet Network Camera, HIKVISION | G26: 1 | I26: In Service | J26: AW5569762 | K26: Spart part KIS
A27: 20 | B27: CCTV Dome | C27: Hikvision | D27: OCCV005BF00001 | E27: DS-2CD3643G2-IZS(2.7-13.5mm) | F27: DS-2CD3643G2-IZS(2.7-13.5mm)_4MP AcuSense Motorized Varifocal Bullet Network Camera, HIKVISION | G27: 1 | I27: In Service | J27: AW5569752 | K27: Spart part KIS
G99: Total | H99: =SUM(H7:H97) -> 34816.24
F100: มีในระบบ Center (Spare parts)
F102: ไม่มีในระบบ Center (Spare parts)
E103: 901-R710-WW00 | F103: มี 2 ตัว ในระบบมี 1 ตัว

Sheet Spare Parts TEACHER DORM
A1: SPARE PART SERVICE TEACHER DORM
L6: การยืมอุปกรณ์
A7: No | B7: Type | C7: Brand | D7: Material Code | E7: Code | F7: PRODUCT NAME | G7: Qty | H7: Cost (Total) | I7: Status | J7: Serail Number | K7: Remark | L7: Name | M7: Date Start | N7: Date End | O7: Project
A8: 1 | B8: AP | C8: Huawei
A9: 2 | B9: AP | C9: Huawei
A10: 3 | B10: AP | C10: Huawei
A11: 4 | B11: AP | C11: Huawei
A12: 5 | B12: AP | C12: Huawei
A13: 6 | B13: AP | C13: Huawei
A14: 7 | B14: AP | C14: Huawei
A15: 8 | B15: AP | C15: Huawei
A16: 9 | B16: CCTV Bullet | C16: Hikvision
A17: 10 | B17: CCTV Bullet | C17: Hikvision
A18: 11 | B18: CCTV Bullet | C18: Hikvision
A19: 12 | B19: CCTV Bullet | C19: Hikvision
... A27: 20 | B27: CCTV Dome | C27: Hikvision
G99: Total | H99: =SUM(H7:H97) -> 0
F100: มีในระบบ Center (Spare parts)
F102: ไม่มีในระบบ Center (Spare parts)
E103: 901-R710-WW00 | F103: มี 2 ตัว ในระบบมี 1 ตัว

Sheet Additional Order BKK
A1: Additional List Spare Part
A4: No | B4: Type | C4: Brand | D4: Code | E4: PRODUCT NAME | F4: Qty | G4: Cost (Total) | H4: Status | I4: Total Cost | J4: Picture | K4: Remark
A5: 1 | B5: Fiber | C5: Interlink | D5: UFP542D31-03 | E5: ST - LC Patch cord OM2, Duplex, UPC-UPC Jacket 3mm. | F5: 4 | G5: 261 | H5: Additional Oder | I5: =SUM(G5*F5) -> 1044
A6: 2 | B6: Fiber | C6: Interlink | D6: UFP546D31-03 | E6: ST - SC Patch cord OM2, Duplex, UPC-UPC Jacket 3mm. | F6: 4 | G6: 254 | H6: Additional Oder | I6: =SUM(G6*F6) -> 1016
A7: 3 | B7: Fiber | C7: Interlink | D7: UFP544D31-03 | E7: ST - ST Patch cord OM2, Duplex, UPC-UPC Jacket 3mm. | F7: 4 | G7: 257 | H7: Additional Oder | I7: =SUM(G7*F7) -> 1028
A8: 4 | B8: Fiber | C8: Interlink | D8: UFP522D31-03 | E8: LC - LC Patch cord OM2, Duplex, UPC-UPC Jacket 3mm. | F8: 6 | G8: 257 | H8: Additional Oder | I8: =SUM(G8*F8) -> 1542
A9: 5 | B9: Fiber | C9: Interlink | D9: UFP466D31-03 | E9: SC - SC Patch cord OM3, Duplex, UPC-UPC Jacket 3mm. | F9: 2 | G9: 285 | H9: Additional Oder | I9: =SUM(G9*F9) -> 570
A10: 6 | B10: FW | C10: Fortinet | E10: Fortinet FortiGate 100D | F10: 1 | G10: 20000 | H10: Additional Oder | I10: =SUM(F10*G10) -> 20000 | K10: ของมือสอง
A11: 7 | B11: FW | C11: Fortinet | E11: Fortinet FortiGate 50E | F11: 1 | G11: 10000 | H11: Additional Oder | I11: =SUM(F11*G11) -> 10000 | K11: ของมือสอง
A12: 8 | B12: NVR | C12: HIKVISION | D12: DS-7716NI-M4 | E12: HIKVISION เครื่องบันทึก IP 16 ช่อง (4 SATA) | F12: 1 | G12: 13800 | H12: Additional Oder | I12: =SUM(F12*G12) -> 13800
A13: 9 | B13: AP-R | C13: Ruckus | D13: 9U1-R550-WW00 | E13: Ruckus R550 | F13: 2 | G13: 13000 | H13: Additional Oder | I13: =SUM(F13*G13) -> 26000
A14: 10 | B14: AP-A | C14: Aruba | D14: R3V46A | E14: Aruba AP-505H (RW) | F14: 2 | G14: 18000 | H14: Additional Oder | I14: =SUM(F14*G14) -> 36000
A15: 10 | B15: AP-A | C15: Aruba | D15: R2H28A | E15: Aruba AP-505 | F15: 2 | G15: 20000 | H15: Additional Oder | I15: =SUM(F15*G15) -> 40000
A16: 10 | B16: FW | C16: Mikrotik | D16: CCR2004-16G-2S+ | E16: CCR2004-16G-2S+ Cloud Core Router, 16 Port Gigabit, 2x10G SFP+ Port, USB 3.0 type-A LTE 4G / 5G Support | F16: 1 | G16: 19000 | H16: Additional Oder | I16: =SUM(F16*G16) -> 19000
A17: 11 | B17: FW | C17: Mikrotik | D17: RB4011iGS+ | E17: Powerful 10xGigabit port router with a Quad-core 1.4Ghz CPU, 1GB RAM, SFP+ 10Gbps cage and desktop case with rack ears | F17: 1 | G17: 8500 | H17: Additional Oder | I17: =SUM(F17*G17) -> 8500
A18: 12 | B18: Media Converter | C18: Link | D18: UT-1310A | E18: Fiber Gigabit Media Converter, 10/100/1000 Mbps ,1000Base-SX/LX , 1-Port RJ45, 1-SFP Slot (Blank), 220m - 110km (SM/MM Support), Indoor Only | F18: 2 | G18: 4000 | H18: Additional Oder | I18: =SUM(F18*G18) -> 8000
A19: 13 | B19: Fiber | C19: Link | D19: UF-0066SM | E19: Duplex Adapter-SC Fiber Optic | F19: 5 | G19: 25 | H19: Additional Oder | I19: =SUM(F19*G19) -> 125
A20: 14 | B20: Switch24 POE | C20: TP-Link | D20: TL-SG3428MP | E20: JetStream 28-Port Gigabit L2 Managed Switch with 24-Port PoE+ 384W | F20: 1 | G20: 11000 | H20: Additional Oder | I20: =SUM(F20*G20) -> 11000
A21: 15 | B21: Mini Gbic | C21: TP-Link | D21: TL-SM311LM | E21: TP-Link LC Multi Mode Transceiver Module | F21: 2 | G21: 1300 | H21: Additional Oder | I21: =SUM(F21*G21) -> 2600
A22: 16 | B22: AP-O | C22: Ruijie | D22: RG-AP180 | E22: RUIJIE Wall Plate Wi-Fi 6 (802.11ax) | F22: 2 | G22: 4400 | H22: Additional Oder | I22: =SUM(F22*G22) -> 8800
A23: 16 | B23: AP-O | C23: Ruijie | D23: RG-AP810-L | E23: RUIJIE AX1800 Wi-Fi 6 SME | F23: 2 | G23: 4200 | H23: Additional Oder | I23: =SUM(F23*G23) -> 8400
... A31: 24 | B31: PABX | C31: NEC | D31: BE113864 | E31: DTZ-24D-3P (BK)TEL DIGITAL KEY TELEPHONE | F31: 2 | G31: 3550 | H31: Additional Oder | I31: =SUM(F31*G31) -> 7100
H32: Total | I32: =SUM(I5:I31) -> 320445

Sheet Additional Order PKT
A1: Additional List Spare Part
A4: No | B4: Type | C4: Brand | D4: Code | E4: PRODUCT NAME | F4: Qty | G4: Cost (Total) | H4: Status | I4: Total Cost | J4: Remark
A5: 1 | B5: Router / Firewall | C5: Mikrotik | D5: RB5009+S+IN | E5: Mikrotik RB5009UG+S+IN CPU Quad-core ARMv8 1.4 GHz 7 Port Gigabit, 1 Port 2.5G | F5: 1 | G5: 8900 | H5: Additional Oder | I5: =SUM(G5*F5) -> 8900
A6: 2 | B6: Router / Firewall | C6: Mikrotik | D6: HAP ax3 | E6: Mikrotik hAP ax3 C53UiG+5HPaxD2HPaxD ROS Lv5 WIFI-6, 4 Port Gigabit, 1 Port 2.5G | F6: 2 | G6: 4500 | H6: Additional Oder | I6: =SUM(G6*F6) -> 9000
A7: 3 | B7: Router / Firewall | C7: Fortigate | D7: FortiGate 50E | E7: Fortinet FortiGate 50E (มือสอง) | F7: 1 | G7: 257 | H7: Additional Oder | I7: =SUM(G7*F7) -> 257
A8: 4 | B8: Router / Firewall | C8: TP-Link | D8: TL-MR100 4G LTE | E8: 300 Mbps Wireless N 4G LTE Router | F8: 1 | G8: 1590 | H8: Additional Oder | I8: =SUM(G8*F8) -> 1590
A9: 5 | B9: Switch | C9: Cisco | D9: CBS350-8P | E9: CISCO CBS350 8 Port CISCO CBS350-8P-E-2G-EU (10'',8 POE,+2 Gigabit) | F9: 2 | G9: 10690 | H9: Additional Oder | I9: =SUM(G9*F9) -> 21380
A10: 6 | B10: Switch | C10: Cisco | D10: CBS350-24FP | E10: CISCO CBS350-24FP-4G-EU Managed 24-port GE, Full PoE, 4x1G SFP | F10: 2 | G10: 27000 | H10: Additional Oder | I10: =SUM(F10*G10) -> 54000
A11: 7 | B11: Switch | C11: HPE | D11: Aruba 2530 | E11: Aruba 2530 8G PoE+ Switch | F11: 2 | G11: 1650 | H11: Additional Oder | I11: =SUM(F11*G11) -> 3300
A12: 8 | B12: Switch | C12: HPE | D12: Aruba 2530 | E12: ARUBA 2530-24-PoE+ Switch (24 x 10/100 PoE+ ports, 2x10/100/1000 ports, 2 SFP ports, 195W) | F12: 1 | G12: 37800 | H12: Additional Oder | I12: =SUM(F12*G12) -> 37800
A13: 9 | B13: UPS | C13: Ablerex | D13: GR-1500 | E13: UPS 1500VA ABLEREX GR1500 | F13: 1 | G13: 4400 | H13: Additional Oder | I13: =SUM(F13*G13) -> 4400
A14: 10 | B14: UPS | C14: Ablerex | D14: EVO-RT2000 | E14: Ablerex EVO-RT2000 Rack 2000VA/1800w with LCD display (EVO-RT2000) | F14: 1 | G14: 22577 | H14: Additional Oder | I14: =SUM(F14*G14) -> 22577
A15: 11 | B15: Fire Alarm | C15: Notifier | D15: SD-651 + Base B401 | E15: Plug In Smoke Detectors + Base | F15: 1 | G15: 1100 | H15: Additional Oder | I15: =SUM(F15*G15) -> 1100
A16: 12 | B16: Fire Alarm | C16: Notifier | D16: FSP-851 + Base B501 | E16: Addressable Photo Electric Smoke Detectors + Base | F16: 1 | G16: 1340 | H16: Additional Oder | I16: =SUM(F16*G16) -> 1340
A17: 13 | B17: Fire Alarm | C17: Bosch | D17: FCP-O320 | E17: Conventional Automatic Fire Detectors | F17: 1 | G17: 2900 | H17: Additional Oder | I17: =SUM(F17*G17) -> 2900
A18: 14 | B18: Fire Alarm | C18: Bosch | D18: FAP-O420 | E18: Optical Smoke Detector | F18: 1 | G18: 2590 | H18: Additional Oder | I18: =SUM(F18*G18) -> 2590
A19: 15 | B19: CCTV | C19: HIKVISION | D19: DS-2CD2021G1-I | E19: 2 MP IR Fixed Network Bullet Camera | F19: 2 | G19: 1850 | H19: Additional Oder | I19: =SUM(F19*G19) -> 3700
A20: 16 | B20: CCTV | C20: HIKVISION | D20: DS-2CD1123G0E-I | E20: 2 MP IR Fixed Network Dome Camera | F20: 2 | G20: 980 | H20: Additional Oder | I20: =SUM(F20*G20) -> 1960
A21: 17 | B21: CCTV | C21: - | D21: IPCXS-ACHT | E21: TESTER CCTV IPCXS-ACHT 5in1 รวมIP/POE max8mpx hdmi inout with RS-485 จอใหญ่7-8" | F21: 1 | G21: 8900 | H21: Additional Oder | I21: =SUM(F21*G21) -> 8900
... A27: 23 | B27: PABX | C27: Grandstream | D27: GXW-4224 | E27: FXS Gateway ขนาด 24-Port FXS, 1 Port LAN | F27: 1 | G27: 31000 | H27: Additional Oder | I27: =SUM(F27*G27) -> 31000
A28: 22 | H28: Additional Oder | I28: =SUM(F28*G28) -> 0
H29: Total | I29: =SUM(I5:I28) -> 271814
